File: assets/dat_files/lectures/1_2_data_mse/force_vs_displ.txt
MTS793|MPT|ENU|1|2|.|/|:|1|0|0|A

Operator Information						Time:	44.94857	Sec	4/10/2014 10:37:22 AM
User	Luecke
Specimen	RD1
Experiment	201404103
material	IF steel
w 	12.695	mm
t	1.193	mm
Extensometer 1	MTS 632-11B-20 S/N 925 G=25.4mm
Gauge length pins free?	yes
Control Program	20140408-tension-relaxation-dispcontrol-v1
Test Notes	programmed relaxation test
User Test Notes	first displacment-controlled test on IF steel
Operator Information End

Data Acquisition						Time:	88.029785	Sec	4/10/2014 10:38:05 AM
Time	Axial Displacement	Axial Force	Axial Strain
Sec	mm	N	mm/mm
69.077316	-10.122135	80.368652	0.00049684133
69.177246	-10.118778	226.39972	0.00053041172
69.277184	-10.115421	345.57449	0.00056398206
69.377121	-10.101993	499.99814	0.00060426648
69.477051	-10.101993	605.74475	0.00064455095
69.576988	-10.095279	674.56409	0.00065126503
69.676926	-10.101993	728.27661	0.00065797905
69.776855	-10.095279	746.7403	0.00067140721
69.876793	-10.095279	755.13293	0.00066469313
69.97673	-10.091922	781.9892	0.00069154945
70.07666	-10.091922	912.91364	0.00071169162
70.176598	-10.081851	1072.3728	0.00077211828
70.276535	-10.071779	1270.438	0.00084597309
70.376465	-10.065065	1480.2527	0.0009198279
70.476402	-10.054995	1651.4614	0.0010138249
70.57634	-10.041566	1777.3505	0.0010809656
70.67627	-10.034852	1842.8125	0.0011615345
70.776207	-10.031495	1923.3815	0.0012353893
70.876144	-10.024781	1950.2378	0.0012958159
70.976074	-10.018067	1985.4866	0.0013629567
71.076012	-10.011353	1995.5576	0.0014300974
71.175949	-10.004639	2012.3429	0.0014838099
71.275879	-9.9979248	2030.8065	0.0015308085
71.375816	-9.9979248	2027.4496	0.001584521
71.475754	-9.9979248	2062.6982	0.0016248055
71.575684	-9.9912109	2054.3059	0.001671804
71.675621	-9.9912109	2092.9116	0.0017188025
71.775558	-9.987854	2082.8406	0.001759087
71.875488	-9.9811392	2097.9473	0.0018127995
71.975426	-9.9811392	2118.0894	0.0018732261
72.075363	-9.9777822	2128.1606	0.0019202246
72.175293	-9.9710684	2144.9458	0.0019672231
72.27523	-9.9643545	2144.9458	0.0020276499
72.375168	-9.9643545	2165.0879	0.0020813623
72.475098	-9.9576406	2149.9812	0.0021417891
72.575035	-9.9576406	2160.0525	0.0021552171
72.674973	-9.9576406	2161.731	0.0022089297
72.774902	-9.9542837	2163.4094	0.0022760704
72.87484	-9.9475689	2186.9087	0.0023230689
72.974777	-9.9475689	2188.5872	0.0023700674
73.074707	-9.940855	2202.0154	0.0024170659
73.174644	-9.9341412	2195.3013	0.0024707785
73.274582	-9.9341412	2210.408	0.002517777
73.374512	-9.9341412	2198.6584	0.0025580614
73.474449	-9.9274273	2212.0864	0.002611774
73.574387	-9.9274273	2207.051	0.0026587725
73.674316	-9.9207125	2213.7651	0.002705771
73.774254	-9.9173555	2238.9429	0.0027594836
73.874191	-9.9173555	2233.9072	0.0028131963
73.974121	-9.9106417	2247.3354	0.0028803369
74.074059	-9.9106417	2238.9429	0.0029206213
74.173996	-9.9039278	2257.4065	0.0029810481
74.273926	-9.9005709	2254.0496	0.0030347607
74.373863	-9.9005709	2255.728	0.0030817592
74.473801	-9.8972139	2247.3354	0.0031220436
74.57373	-9.893857	2243.9785	0.0031824701
74.673668	-9.8871422	2279.2273	0.0032294688
74.773605	-9.8871422	2259.085	0.0032831812
74.873535	-9.8837852	2269.1563	0.0033368939
74.973473	-9.8804283	2255.728	0.0033771782
75.07341	-9.8804283	2279.2273	0.0034174628
75.17334	-9.8770714	2270.8347	0.0034644613
75.273277	-9.8770714	2275.8704	0.0035181739
75.373215	-9.8737144	2279.2273	0.0035718863
75.473145	-9.8703575	2272.5132	0.003625599
75.573082	-9.8670006	2302.7266	0.0036524553
75.673019	-9.8602867	2289.2983	0.003719596
75.772949	-9.8602867	2301.0481	0.0037598803
75.872887	-9.8569288	2292.6555	0.0038068788
75.972824	-9.850215	2312.7976	0.0038538775
76.072754	-9.850215	2306.0835	0.003921018
76.172691	-9.850215	2307.7622	0.0039747306
76.272629	-9.8401442	2319.5117	0.0040217293
76.372559	-9.8401442	2307.7622	0.0040687276
76.472496	-9.8401442	2327.9043	0.0041224402
76.572433	-9.8334303	2302.7266	0.004169439
76.672363	-9.8300734	2321.1902	0.0042164372
76.772301	-9.8300734	2321.1902	0.0042701499
76.872238	-9.8233585	2329.5828	0.0043305764
76.972168	-9.8166447	2322.8689	0.0043641469
77.072105	-9.8200016	2326.2258	0.0044245734
77.172043	-9.8166447	2334.6184	0.0044648582
77.271973	-9.8132877	2329.5828	0.0045118565
77.37191	-9.8065739	2348.0466	0.0045588552
77.471848	-9.8099308	2332.9399	0.0046058535
77.571777	-9.8065739	2356.4392	0.00466628
77.671715	-9.7965021	2344.6895	0.0047401348
77.771652	-9.7965021	2339.6541	0.004760277
77.871582	-9.7931452	2346.3682	0.004820704
77.971519	-9.7931452	2351.4036	0.004854274
78.071457	-9.7864313	2361.4749	0.0049012727
78.171387	-9.7864313	2353.082	0.0049751275
78.271324	-9.7797174	2369.8674	0.0050019836
78.371262	-9.7797174	2354.7607	0.0050624106
78.471191	-9.7797174	2379.9385	0.005102695
78.571129	-9.7730036	2368.1887	0.0051631215
78.671066	-9.7696466	2356.4392	0.0052034059
78.770996	-9.7696466	2373.2244	0.0052638324
78.870934	-9.7629318	2369.8674	0.0052974029
78.970871	-9.7595749	2369.8674	0.0053444016
79.070801	-9.7595749	2383.2954	0.0054048281
79.170738	-9.752861	2400.0806	0.0054518268
79.270676	-9.752861	2378.26	0.005505539
79.370605	-9.7461472	2393.3665	0.0055458238
79.470543	-9.7461472	2396.7234	0.0056062504
79.57048	-9.7427902	2390.0095	0.005659963
79.67041	-9.7394333	2401.759	0.0057069613
79.770348	-9.7360764	2386.6526	0.00575396
79.870285	-9.7327185	2405.116	0.0058009583
79.970215	-9.7327185	2393.3665	0.005847957
80.070152	-9.7260046	2406.7944	0.0059016696
80.17009	-9.7226477	2406.7944	0.005941954
80.27002	-9.7226477	2425.2583	0.0060090944
80.369957	-9.7192907	2420.2227	0.006062807
80.469894	-9.7159338	2406.7944	0.0061165197
80.569824	-9.7125769	2437.0078	0.0061635184
80.669762	-9.705863	2416.8657	0.006217231
80.769699	-9.7025051	2430.2937	0.0062575154
80.869629	-9.6991482	2421.9011	0.0063179419
80.969566	-9.6991482	2426.9368	0.0063649402
81.069504	-9.6991482	2426.9368	0.0064119389
81.169434	-9.6924343	2428.6152	0.0064522233
81.269371	-9.6890774	2426.9368	0.006499222
81.369308	-9.6857204	2431.9724	0.0065596486
81.469238	-9.6823635	2460.5071	0.0066066468
81.569176	-9.6823635	2433.6509	0.0066536455
81.669113	-9.6790066	2438.6863	0.0067006443
81.769043	-9.6756496	2433.6509	0.0067543564
81.86898	-9.6689348	2447.0791	0.0067946413
81.968918	-9.6689348	2448.7576	0.0068483534
82.068848	-9.658864	2453.793	0.0068886383
82.168785	-9.662221	2452.1145	0.0069490648
82.268723	-9.658864	2445.4004	0.0069893491
82.368652	-9.6521502	2480.6494	0.0070564901
82.46859	-9.6487932	2465.5427	0.00709006
82.568527	-9.6487932	2467.2212	0.0071572009
82.668457	-9.6420794	2457.1501	0.0072109136
82.768394	-9.6420794	2463.8643	0.0072511979
82.868332	-9.6387215	2472.2568	0.0072981967
82.968262	-9.6286507	2468.8997	0.0073586232
83.068199	-9.6286507	2475.6138	0.0074056215
83.168137	-9.6320076	2473.9353	0.0074459058
83.268066	-9.6219368	2487.3635	0.0075130467
83.368004	-9.6185799	2475.6138	0.0075533311
83.467941	-9.6185799	2478.9709	0.0075936154
83.567871	-9.6152229	2484.0063	0.0076406142
83.667809	-9.611866	2478.9709	0.0076943268
83.767746	-9.611866	2494.0776	0.0077413251
83.867676	-9.6051512	2477.2922	0.0077950377
83.967613	-9.6051512	2500.7915	0.0078286082
84.067551	-9.6051512	2495.7561	0.0078957491
84.16748	-9.5950804	2504.1487	0.0079360334
84.267418	-9.5917234	2504.1487	0.0079964604
84.367355	-9.5883665	2509.1841	0.0080501726
84.467285	-9.5883665	2505.8271	0.0080971709
84.567223	-9.5850096	2495.7561	0.0081374552
84.66716	-9.5816526	2522.6123	0.0081978822
84.76709	-9.5782957	2502.4702	0.0082515944
84.867027	-9.5749378	2517.5769	0.0082851648
84.966965	-9.568224	2512.5413	0.0083388779
85.066895	-9.568224	2505.8271	0.0083858762
85.166832	-9.5581532	2517.5769	0.0084395884
85.266769	-9.5615101	2517.5769	0.0084798727
85.366699	-9.5547962	2544.4331	0.0085335858
85.466637	-9.5547962	2519.2554	0.0085940128
85.566574	-9.5480824	2532.6833	0.0086342972
85.666504	-9.5480824	2515.8982	0.0086880093
85.766441	-9.5447245	2546.1116	0.0087350076
85.866379	-9.5380106	2542.7546	0.0087954346
85.966309	-9.5380106	2525.9695	0.0088424329
86.066246	-9.5380106	2557.8613	0.008896146
86.166183	-9.5279398	2537.719	0.0089632859
86.266113	-9.5212259	2546.1116	0.0090035712
86.366051	-9.5245829	2532.6833	0.0090371408
86.465988	-9.5245829	2547.79	0.00908414
86.565918	-9.517869	2551.1472	0.0091378521
86.665855	-9.5111542	2569.6108	0.0091915652
86.765793	-9.5077972	2554.5042	0.0092519913
86.865723	-9.5077972	2542.7546	0.0092989895
86.96566	-9.5077972	2566.2539	0.00933256
87.065598	-9.5010834	2556.1826	0.0093997009
87.165527	-9.4977264	2564.5754	0.0094399853
87.265465	-9.4977264	2549.4688	0.0094802696
87.365402	-9.4910126	2567.9324	0.0095272688
87.465332	-9.4842978	2572.968	0.009580981
87.565269	-9.4809408	2574.6465	0.009641408
87.665207	-9.4809408	2571.2893	0.0096884063
87.765137	-9.4842978	2566.2539	0.0097421184
87.865074	-9.474227	2593.1101	0.0097958315
87.965012	-9.47087	2578.0034	0.0098562576

Data Acquisition						Time:	373.9035	Sec	4/10/2014 10:42:51 AM
Time	Axial Displacement	Axial Force	Axial Strain
Sec	mm	N	mm/mm
89.040207	-9.4675131	2415.187	0.009889828
90.040207	-9.4675131	2415.187	0.0099032568
91.040207	-9.47087	2391.688	0.0099099707
92.040207	-9.4675131	2371.5459	0.009889828
93.040207	-9.47087	2358.1177	0.0099099707
94.040207	-9.4675131	2383.2954	0.0099166846
95.040207	-9.4675131	2344.6895	0.009889828
96.040207	-9.4675131	2311.1191	0.009889828
97.040207	-9.474227	2309.4407	0.0098764002
98.040207	-9.47087	2301.0481	0.0098764002
99.040207	-9.4675131	2282.5842	0.0098764002
100.04021	-9.47087	2322.8689	0.009889828
101.04021	-9.47087	2331.2615	0.0098831141
102.04021	-9.4641562	2339.6541	0.0099032568
103.04021	-9.47087	2317.8333	0.0098764002
104.04021	-9.4675131	2349.7251	0.0098831141
105.04021	-9.4675131	2329.5828	0.0098965419
106.04021	-9.474227	2363.1533	0.0098965419
107.04021	-9.47087	2336.2969	0.0098965419
108.04021	-9.4675131	2388.3311	0.0099368272
109.04021	-9.47087	2368.1887	0.0099032568
110.04021	-9.47087	2376.5813	0.0099166846
111.04021	-9.47087	2359.7961	0.0099099707
112.04021	-9.4675131	2368.1887	0.0099099707
113.04021	-9.4675131	2354.7607	0.0099099707
114.04021	-9.47087	2326.2258	0.0099032568
115.04021	-9.474227	2351.4036	0.0098965419
116.04021	-9.4675131	2282.5842	0.0098965419
117.04021	-9.4675131	2297.6909	0.0098965419
118.04021	-9.47087	2287.6199	0.009889828
119.04021	-9.47087	2312.7976	0.0098965419
120.04021	-9.4675131	2284.2629	0.009889828
121.04021	-9.47087	2289.2983	0.009889828
122.04021	-9.474227	2282.5842	0.0098831141
123.04021	-9.4675131	2290.9771	0.0099099707
124.04021	-9.4675131	2274.1917	0.0098764002
125.04021	-9.47087	2233.9072	0.0098831141
126.04021	-9.4675131	2247.3354	0.009889828
127.04021	-9.474227	2321.1902	0.0099032568
128.04021	-9.4675131	2314.4763	0.0098965419
129.04021	-9.47087	2309.4407	0.0099032568
130.04021	-9.47087	2319.5117	0.0099166846
131.04021	-9.47087	2316.1548	0.0099032568
132.04021	-9.47087	2272.5132	0.0098764002
133.04021	-9.4675131	2324.5474	0.0099032568
134.04021	-9.4675131	2294.334	0.0098831141
135.04021	-9.47087	2317.8333	0.009889828
136.04021	-9.4675131	2353.082	0.0099099707
137.04021	-9.474227	2287.6199	0.009889828
138.04021	-9.47087	2296.0125	0.009889828
139.04021	-9.474227	2301.0481	0.009889828
140.04021	-9.47087	2349.7251	0.0099233985
141.04021	-9.4675131	2343.011	0.0099099707
142.04021	-9.47087	2324.5474	0.0099099707
143.04021	-9.47087	2337.9756	0.0099099707
144.04021	-9.474227	2287.6199	0.0098831141
145.04021	-9.4675131	2327.9043	0.0099032568
146.04021	-9.4675131	2353.082	0.0099099707
147.04021	-9.47087	2311.1191	0.0099032568
148.04021	-9.4675131	2349.7251	0.0099233985
149.04021	-9.4675131	2376.5813	0.0099301124
150.04021	-9.47087	2376.5813	0.0099233985
151.04021	-9.4675131	2356.4392	0.0099166846
152.04021	-9.47087	2299.3696	0.0099099707
153.04021	-9.47087	2299.3696	0.0099032568
154.04021	-9.47087	2299.3696	0.0099099707
155.04021	-9.474227	2346.3682	0.0099166846
156.04021	-9.474227	2343.011	0.0099166846
157.04021	-9.4675131	2343.011	0.0099166846
158.04021	-9.4675131	2297.6909	0.0099032568
159.04021	-9.4675131	2371.5459	0.0099368272
160.04021	-9.47087	2373.2244	0.0099301124
161.04021	-9.47087	2363.1533	0.0099301124
162.04021	-9.4675131	2359.7961	0.0099233985
163.04021	-9.4675131	2337.9756	0.0099099707
164.04021	-9.4775839	2351.4036	0.0099233985
165.04021	-9.4675131	2329.5828	0.0099301124
166.04021	-9.47087	2272.5132	0.0099099707
167.04021	-9.47087	2316.1548	0.0099166846
168.04021	-9.47087	2311.1191	0.0099166846
169.04021	-9.4675131	2307.7622	0.0099166846
170.04021	-9.4675131	2353.082	0.0099233985
171.04021	-9.4675131	2280.9058	0.0099099707
172.04021	-9.4675131	2282.5842	0.0099166846
173.04021	-9.4675131	2284.2629	0.0099099707
174.04021	-9.474227	2334.6184	0.0099435411
175.04021	-9.47087	2304.405	0.0099166846
176.04021	-9.47087	2322.8689	0.0099233985
177.04021	-9.4675131	2326.2258	0.0099301124
178.04021	-9.47087	2316.1548	0.0099233985
179.04021	-9.4675131	2282.5842	0.0099099707
180.04021	-9.4675131	2297.6909	0.0098965419
181.04021	-9.4641562	2356.4392	0.0099368272
182.04021	-9.4675131	2337.9756	0.0099301124
183.04021	-9.47087	2341.3325	0.0099233985
184.04021	-9.47087	2368.1887	0.0099368272
185.04021	-9.47087	2332.9399	0.0099166846
186.04021	-9.47087	2306.0835	0.0099233985
187.04021	-9.47087	2304.405	0.0099166846
188.04021	-9.47087	2302.7266	0.0099166846
189.04021	-9.4675131	2311.1191	0.0099301124
190.04021	-9.4775839	2337.9756	0.0099301124
191.04021	-9.47087	2294.334	0.0099233985
192.04021	-9.4675131	2339.6541	0.0099368272
193.04021	-9.4675131	2341.3325	0.0099233985
194.04021	-9.47087	2337.9756	0.0099301124
195.04021	-9.47087	2319.5117	0.0099233985
196.04021	-9.4675131	2297.6909	0.0099099707
197.04021	-9.47087	2311.1191	0.0099233985
198.04021	-9.4675131	2299.3696	0.0099166846
199.04021	-9.47087	2373.2244	0.0099435411
200.04021	-9.4675131	2364.8318	0.0099368272
201.04021	-9.47087	2358.1177	0.0099301124
202.04021	-9.47087	2341.3325	0.0099301124
203.04021	-9.47087	2314.4763	0.0099233985
204.04021	-9.47087	2285.9414	0.0099166846
205.04021	-9.4675131	2279.2273	0.0099099707
206.04021	-9.47087	2314.4763	0.0099301124
207.04021	-9.47087	2294.334	0.0099099707
208.04021	-9.4675131	2297.6909	0.0099166846
209.04021	-9.474227	2317.8333	0.0099166846
210.04021	-9.47087	2307.7622	0.0099166846
211.04021	-9.47087	2321.1902	0.0099166846
212.04021	-9.4675131	2279.2273	0.0099099707
213.04021	-9.47087	2289.2983	0.0099099707
214.04021	-9.47087	2322.8689	0.0099166846
215.04021	-9.47087	2290.9771	0.0099166846
216.04021	-9.4675131	2314.4763	0.0099233985
217.04021	-9.474227	2317.8333	0.0099032568
218.04021	-9.4675131	2343.011	0.0099233985
219.04021	-9.47087	2297.6909	0.0099166846
220.04021	-9.47087	2312.7976	0.0099301124
221.04021	-9.4675131	2270.8347	0.0099099707
222.04021	-9.4775839	2237.2644	0.009889828
223.04021	-9.47087	2294.334	0.0099233985
224.04021	-9.47087	2299.3696	0.0099233985
225.04021	-9.4675131	2252.3711	0.0099032568
226.04021	-9.47087	2314.4763	0.0099166846
227.04021	-9.47087	2322.8689	0.0099233985
228.04021	-9.4675131	2274.1917	0.0099099707
229.04021	-9.4675131	2254.0496	0.0099032568
230.04021	-9.47087	2238.9429	0.0099032568
231.04021	-9.47087	2245.657	0.0099032568
232.04021	-9.4675131	2235.5857	0.0098965419
233.04021	-9.4675131	2272.5132	0.0099099707
234.04021	-9.4675131	2237.2644	0.0098965419
235.04021	-9.4641562	2252.3711	0.0099032568
236.04021	-9.47087	2259.085	0.0099099707
237.04021	-9.474227	2269.1563	0.0099032568
238.04021	-9.4675131	2245.657	0.009889828
239.04021	-9.4675131	2272.5132	0.0099166846
240.04021	-9.4675131	2292.6555	0.0099166846
241.04021	-9.4675131	2259.085	0.0099099707
242.04021	-9.474227	2297.6909	0.0099099707
243.04021	-9.47087	2259.085	0.0099099707
244.04021	-9.474227	2257.4065	0.0099032568
245.04021	-9.474227	2275.8704	0.0099099707
246.04021	-9.4675131	2290.9771	0.0099166846
247.04021	-9.4675131	2274.1917	0.0099166846
248.04021	-9.47087	2344.6895	0.0099301124
249.04021	-9.4675131	2336.2969	0.0099301124
250.04021	-9.474227	2329.5828	0.0099301124
251.04021	-9.47087	2327.9043	0.0099301124
252.04021	-9.4675131	2285.9414	0.0099166846
253.04021	-9.4675131	2255.728	0.0099099707
254.04021	-9.474227	2222.1577	0.0098965419
255.04021	-9.47087	2205.3726	0.009889828
256.04022	-9.47087	2277.5488	0.0099099707
257.04022	-9.47087	2259.085	0.0099032568
258.04022	-9.47087	2202.0154	0.0098965419
259.04022	-9.4675131	2255.728	0.0099166846
260.04022	-9.474227	2311.1191	0.0099233985
261.04022	-9.4675131	2250.6924	0.0099099707
262.04022	-9.4675131	2294.334	0.0099233985
263.04022	-9.4675131	2284.2629	0.0099099707
264.04022	-9.4675131	2284.2629	0.0099233985
265.04022	-9.4675131	2344.6895	0.0099301124
266.04022	-9.47087	2343.011	0.0099233985
267.04022	-9.47087	2317.8333	0.0099368272
268.04022	-9.474227	2279.2273	0.0099099707
269.04022	-9.47087	2356.4392	0.0099368272
270.04022	-9.47087	2296.0125	0.0099301124
271.04022	-9.47087	2302.7266	0.0099166846
272.04022	-9.47087	2353.082	0.0099435411
273.04022	-9.47087	2292.6555	0.0099301124
274.04022	-9.4675131	2329.5828	0.0099301124
275.04022	-9.4675131	2364.8318	0.0099368272
276.04022	-9.47087	2311.1191	0.0099301124
277.04022	-9.4675131	2302.7266	0.0099301124
278.04022	-9.4675131	2359.7961	0.009950255
279.04022	-9.47087	2294.334	0.0099368272
280.04022	-9.47087	2299.3696	0.0099301124
281.04022	-9.47087	2309.4407	0.0099233985
282.04022	-9.47087	2332.9399	0.0099435411
283.04022	-9.47087	2386.6526	0.0099569689
284.04022	-9.4675131	2316.1548	0.0099233985
285.04022	-9.47087	2304.405	0.0099233985
286.04022	-9.4675131	2371.5459	0.0099569689
287.04022	-9.4675131	2371.5459	0.0099435411
288.04022	-9.4675131	2312.7976	0.0099301124
289.04022	-9.4675131	2287.6199	0.0099301124
290.04022	-9.47087	2307.7622	0.0099233985
291.04022	-9.474227	2302.7266	0.0099166846
292.04022	-9.47087	2282.5842	0.0099301124
293.04022	-9.4675131	2296.0125	0.0099166846
294.04022	-9.4675131	2324.5474	0.0099301124
295.04022	-9.47087	2327.9043	0.0099435411
296.04022	-9.47087	2274.1917	0.0099166846
297.04022	-9.4675131	2247.3354	0.0099099707
298.04022	-9.47087	2200.3369	0.0098965419
299.04022	-9.474227	2243.9785	0.0099099707
300.04022	-9.474227	2255.728	0.0099166846
301.04022	-9.4675131	2250.6924	0.0099166846
302.04022	-9.47087	2279.2273	0.0099099707
303.04022	-9.4675131	2311.1191	0.0099301124
304.04022	-9.4675131	2312.7976	0.0099301124
305.04022	-9.474227	2272.5132	0.0099099707
306.04022	-9.47087	2272.5132	0.0099099707
307.04022	-9.47087	2262.4421	0.0099099707
308.04022	-9.4675131	2311.1191	0.0099166846
309.04022	-9.4675131	2306.0835	0.0099301124
310.04022	-9.47087	2269.1563	0.0099099707
311.04022	-9.47087	2254.0496	0.0099099707
312.04022	-9.4675131	2247.3354	0.0098965419
313.04022	-9.47087	2250.6924	0.0099099707
314.04022	-9.4675131	2265.7991	0.0099099707
315.04022	-9.47087	2272.5132	0.0099099707
316.04022	-9.474227	2257.4065	0.0099099707
317.04022	-9.47087	2245.657	0.0099032568
318.04022	-9.47087	2299.3696	0.0099032568
319.04022	-9.47087	2259.085	0.0099032568
320.04022	-9.47087	2316.1548	0.0099301124
321.04022	-9.47087	2326.2258	0.0099301124
322.04022	-9.47087	2307.7622	0.0099368272
323.04022	-9.47087	2391.688	0.009950255
324.04022	-9.4675131	2371.5459	0.0099435411
325.04022	-9.47087	2358.1177	0.0099368272
326.04022	-9.47087	2312.7976	0.0099368272
327.04022	-9.4675131	2314.4763	0.0099301124
328.04022	-9.47087	2260.7637	0.0099166846
329.04022	-9.47087	2186.9087	0.009889828
330.04022	-9.474227	2270.8347	0.0099099707
331.04022	-9.4675131	2264.1206	0.0099166846
332.04022	-9.47087	2299.3696	0.0099233985
333.04022	-9.4675131	2302.7266	0.0099099707
334.04022	-9.4641562	2307.7622	0.0099368272
335.04022	-9.47087	2356.4392	0.0099435411
336.04022	-9.47087	2361.4749	0.0099435411
337.04022	-9.4675131	2327.9043	0.0099368272
338.04022	-9.47087	2317.8333	0.0099435411
339.04022	-9.47087	2317.8333	0.0099435411
340.04022	-9.4675131	2331.2615	0.0099368272
341.04022	-9.47087	2292.6555	0.0099233985
342.04022	-9.47087	2327.9043	0.0099301124
343.04022	-9.47087	2287.6199	0.0099166846
344.04022	-9.4641562	2337.9756	0.0099435411
345.04022	-9.4641562	2343.011	0.009950255
346.04022	-9.47087	2312.7976	0.0099435411
347.04022	-9.47087	2307.7622	0.0099301124
348.04022	-9.47087	2311.1191	0.0099435411
349.04022	-9.47087	2343.011	0.009950255
350.04022	-9.4675131	2349.7251	0.009950255
351.04022	-9.4675131	2334.6184	0.0099435411
352.04022	-9.47087	2356.4392	0.009950255
353.04022	-9.47087	2369.8674	0.0099368272
354.04022	-9.4675131	2386.6526	0.0099703968
355.04022	-9.4641562	2329.5828	0.0099435411
356.04022	-9.47087	2337.9756	0.0099569689
357.04022	-9.474227	2353.082	0.009950255
358.04022	-9.474227	2317.8333	0.0099368272
359.04022	-9.4675131	2314.4763	0.0099435411
360.04022	-9.47087	2327.9043	0.0099435411
361.04022	-9.47087	2381.6169	0.0099703968
362.04022	-9.474227	2349.7251	0.009950255
363.04022	-9.47087	2403.4375	0.0099636829
364.04022	-9.474227	2440.365	0.0099972533
365.04022	-9.47087	2346.3682	0.0099703968
366.04022	-9.47087	2358.1177	0.0099703968
367.04022	-9.47087	2356.4392	0.0099703968
368.04022	-9.474227	2306.0835	0.0099569689
369.04022	-9.4675131	2361.4749	0.0099771116
370.04022	-9.47087	2306.0835	0.0099569689
371.04022	-9.47087	2233.9072	0.0099368272
372.04022	-9.47087	2245.657	0.0099435411
373.04022	-9.474227	2227.1931	0.0099368272

Data Acquisition						Time:	394.06152	Sec	4/10/2014 10:43:11 AM
Time	Axial Displacement	Axial Force	Axial Strain
Sec	mm	N	mm/mm
374.01385	-9.4675131	2202.0154	0.0099233985
374.11377	-9.4675131	2222.1577	0.0099233985
374.21371	-9.4675131	2292.6555	0.009950255
374.31366	-9.4641562	2393.3665	0.0099838255
374.41357	-9.4641562	2477.2922	0.010017396
374.51352	-9.4607992	2576.325	0.010071108
374.61346	-9.4507275	2589.7532	0.010138249
374.71338	-9.4473705	2616.6094	0.010198676
374.81332	-9.4473705	2593.1101	0.010252388
374.91327	-9.4406567	2598.1458	0.010299386
375.01318	-9.4372997	2593.1101	0.010346386
375.11313	-9.4305859	2596.4673	0.010400098
375.21307	-9.4305859	2608.2168	0.01045381
375.31299	-9.4272289	2591.4316	0.010500809
375.41293	-9.4205141	2616.6094	0.010554521
375.51288	-9.423872	2599.8242	0.01060152
375.61279	-9.4138002	2621.645	0.010655233
375.71274	-9.4138002	2608.2168	0.010708945
375.81268	-9.4138002	2604.8599	0.010762658
375.9126	-9.4037294	2618.2878	0.010802942
376.01254	-9.4003725	2613.2524	0.010849941
376.11249	-9.3970156	2625.002	0.010896939
376.2124	-9.4003725	2614.9309	0.010950652
376.31235	-9.3970156	2635.0732	0.011004364
376.41229	-9.3869438	2626.6807	0.011058077
376.51221	-9.3903008	2630.0376	0.011098362
376.61215	-9.3835869	2619.9666	0.011152074
376.7121	-9.3802299	2613.2524	0.011192358
376.81201	-9.3735161	2648.5012	0.011239357
376.91196	-9.3701591	2630.0376	0.011286356
377.0119	-9.3701591	2646.8228	0.011346782
377.11182	-9.3668022	2635.0732	0.011400495
377.21176	-9.3600883	2650.1799	0.011454207
377.31171	-9.3600883	2651.8584	0.01150792
377.41162	-9.3533735	2653.5369	0.011554918
377.51157	-9.3533735	2636.7517	0.01160863
377.61151	-9.3466597	2638.4302	0.011662344
377.71143	-9.3433027	2666.9651	0.011702628
377.81137	-9.3399458	2651.8584	0.011749626
377.91132	-9.3399458	2660.251	0.011796624
378.01123	-9.3332319	2651.8584	0.011850337
378.11118	-9.329875	2666.9651	0.011890622
378.21112	-9.3231602	2656.8938	0.011957763
378.31104	-9.3198032	2653.5369	0.012004761
378.41098	-9.3164463	2666.9651	0.012058473
378.51093	-9.3130894	2663.6079	0.012098758
378.61084	-9.3130894	2685.4287	0.012145757
378.71078	-9.3097324	2663.6079	0.012206183
378.81073	-9.3063755	2672.0005	0.012246468
378.91064	-9.2996616	2663.6079	0.01230018
379.01059	-9.2996616	2677.0361	0.012347179
379.11053	-9.2963037	2673.6792	0.012387463
379.21045	-9.2929468	2675.3577	0.012441176
379.31039	-9.2895899	2692.1428	0.012494888
379.41034	-9.282876	2682.0718	0.012535173
379.51025	-9.2795191	2698.8569	0.0125956
379.6102	-9.2761621	2675.3577	0.012642598
379.71014	-9.2694483	2695.4998	0.012696311
379.81006	-9.2694483	2685.4287	0.012750023
379.91	-9.2593765	2700.5354	0.012790307
380.00995	-9.2627335	2685.4287	0.012844021
380.10986	-9.2560196	2693.8213	0.012884305
380.20981	-9.2526627	2693.8213	0.012944731
380.30975	-9.2526627	2692.1428	0.01299173
380.40967	-9.2493057	2712.2849	0.013045442
380.50961	-9.2425919	2698.8569	0.013105869
380.60956	-9.2425919	2710.6064	0.013139439
380.70947	-9.2325201	2700.5354	0.01320658
380.80942	-9.2291632	2710.6064	0.01324015
380.90936	-9.2291632	2702.2139	0.013293863
381.00928	-9.2258062	2718.999	0.013334148
381.10922	-9.2224493	2713.9636	0.013394574
381.20917	-9.2190924	2713.9636	0.013441573
381.30908	-9.2123785	2720.6777	0.013488571
381.40903	-9.2090216	2710.6064	0.013535569
381.50897	-9.2056646	2729.0701	0.013589283
381.60889	-9.2090216	2715.6421	0.013642995
381.70883	-9.1989498	2729.0701	0.013683279
381.80878	-9.1989498	2712.2849	0.013736992
381.90869	-9.1922359	2737.4626	0.01378399
382.00864	-9.188879	2727.3916	0.013837703
382.10858	-9.1855221	2724.0347	0.013891416
382.2085	-9.1821651	2735.7839	0.013945128
382.30844	-9.1788082	2734.1055	0.013992126
382.40839	-9.1687365	2744.1768	0.014039125
382.5083	-9.1687365	2725.7131	0.014099551
382.60825	-9.1653795	2745.8552	0.014133122
382.70819	-9.1620226	2730.7485	0.014186835
382.80811	-9.1553087	2752.5693	0.014247261
382.90805	-9.1553087	2747.5337	0.014294259
383.008	-9.1519518	2749.2122	0.01432783
383.10791	-9.141881	2745.8552	0.014381543
383.20786	-9.1452379	2752.5693	0.014428541
383.3078	-9.141881	2755.9263	0.014488968
383.40771	-9.1351662	2747.5337	0.01454268
383.50766	-9.1351662	2762.6404	0.014582965
383.6076	-9.1284523	2749.2122	0.014636678
383.70752	-9.1250954	2765.9973	0.014683676
383.80746	-9.1217384	2759.2832	0.014730674
383.90741	-9.1183815	2767.676	0.014777672
384.00732	-9.1116676	2755.9263	0.014838099
384.10727	-9.1150246	2774.3899	0.014891812
384.20721	-9.1015959	2772.7114	0.014938811
384.30713	-9.1049528	2760.9619	0.014999237
384.40707	-9.0982389	2776.0686	0.015032807
384.50702	-9.1015959	2772.7114	0.015079807
384.60693	-9.094882	2786.1396	0.015140233
384.70688	-9.0915251	2771.033	0.015187231
384.80682	-9.0814543	2784.4612	0.015240944
384.90674	-9.0814543	2777.7471	0.015281228
385.00668	-9.0814543	2789.4966	0.015334941
385.10663	-9.0680256	2784.4612	0.01538194
385.20654	-9.0747395	2779.4255	0.015442366
385.30649	-9.0646687	2799.5679	0.015496079
385.40643	-9.0646687	2781.104	0.015543077
385.50635	-9.0646687	2792.8538	0.015576648
385.60629	-9.0613117	2786.1396	0.015630361
385.70624	-9.0579548	2804.6033	0.015690787
385.80615	-9.0512409	2781.104	0.015731072
385.9061	-9.047884	2801.2463	0.015764641
386.00604	-9.0445261	2792.8538	0.015825069
386.10596	-9.0378122	2801.2463	0.01587878
386.2059	-9.0378122	2807.9604	0.015919065
386.30585	-9.0310984	2807.9604	0.015979491
386.40576	-9.0243845	2809.6389	0.016033204
386.50571	-9.0243845	2802.9248	0.016080203
386.60565	-9.0210276	2821.3884	0.016133916
386.70557	-9.0176706	2801.2463	0.016180914
386.80551	-9.0109558	2816.353	0.016227912
386.90546	-9.0109558	2816.353	0.016281625
387.00537	-9.0042419	2821.3884	0.016328624
387.10532	-9.000885	2829.7813	0.016382337
387.20526	-8.9975281	2812.9958	0.016436048
387.30518	-8.9975281	2816.353	0.016489761
387.40512	-8.9874573	2812.9958	0.016530046
387.50507	-8.9840994	2834.8167	0.01657033
387.60498	-8.9874573	2821.3884	0.016624043
387.70493	-8.9807425	2836.4951	0.016684469
387.80487	-8.9740286	2821.3884	0.016731467
387.90479	-8.9706717	2831.4597	0.016765038
388.00473	-8.9706717	2831.4597	0.016818751
388.10468	-8.9639578	2829.7813	0.016872464
388.20459	-8.9572439	2841.5308	0.016939605
388.30453	-8.9606009	2831.4597	0.016986603
388.40448	-8.953887	2846.5664	0.017026886
388.50439	-8.9471722	2834.8167	0.017080599
388.60434	-8.9404583	2854.959	0.017134313
388.70428	-8.9404583	2833.1382	0.017167883
388.8042	-8.9371014	2866.7085	0.017235024
388.90414	-8.9303875	2851.6018	0.01729545
389.00409	-8.9303875	2841.5308	0.017349163
389.104	-8.9303875	2838.1738	0.017382734
389.20395	-8.9236736	2843.2092	0.017429732
389.30389	-8.9203157	2866.7085	0.01747673
389.40381	-8.9136019	2848.2449	0.017523728
389.50375	-8.9136019	2868.387	0.017564014
389.6037	-8.906888	2858.3159	0.017637867
389.70361	-8.9035311	2868.387	0.017684866
389.80356	-8.9001741	2856.6375	0.017738579
389.9035	-8.8968172	2868.387	0.017785577
390.00342	-8.8934603	2865.03	0.017832575
390.10336	-8.8901024	2863.3516	0.017879574
390.20331	-8.8901024	2876.7798	0.017919859
390.30322	-8.8766747	2859.9944	0.017980285
390.40317	-8.8766747	2878.4583	0.01802057
390.50311	-8.8733177	2866.7085	0.018080996
390.60303	-8.8733177	2885.1724	0.018121282
390.70297	-8.8666039	2873.4226	0.018174993
390.80292	-8.8565321	2876.7798	0.018235421
390.90283	-8.8565321	2866.7085	0.018268991
391.00278	-8.8565321	2868.387	0.018322702
391.10272	-8.8531752	2896.9219	0.018369701
391.20264	-8.8498182	2880.1367	0.018423414
391.30258	-8.8431044	2900.2791	0.018470412
391.40253	-8.8397474	2883.4937	0.018537553
391.50244	-8.8330336	2895.2434	0.018584551
391.60239	-8.8363905	2878.4583	0.01863155
391.70233	-8.8330336	2905.3145	0.018671835
391.80225	-8.8263187	2896.9219	0.018725548
391.90219	-8.8196049	2893.5649	0.018772546
392.00214	-8.812891	2905.3145	0.018819544
392.10205	-8.8196049	2896.9219	0.018866543
392.202	-8.8095341	2912.0286	0.018920256
392.30194	-8.8028202	2890.2078	0.018987397
392.40186	-8.8028202	2903.636	0.019020967
392.5018	-8.7994633	2898.6003	0.019067965
392.60175	-8.7961054	2933.8494	0.019141819
392.70166	-8.7893915	2912.0286	0.019195532
392.80161	-8.7860346	2903.636	0.019235818
392.90155	-8.7860346	2912.0286	0.019282816
393.00146	-8.7726068	2910.3501	0.019336527
393.10141	-8.7726068	2920.4211	0.01939024
393.20135	-8.7726068	2903.636	0.019437239
393.30127	-8.765893	2922.0996	0.019484237
393.40121	-8.7625351	2908.6716	0.019544665
393.50116	-8.7591782	2930.4922	0.019578235
393.60107	-8.7558212	2922.0996	0.019631946
393.70102	-8.7558212	2922.0996	0.019672232
393.80096	-8.7491074	2937.2063	0.019732658
393.90088	-8.7491074	2932.1709	0.019786371
394.00082	-8.7423935	2932.1709	0.019826654

Data Acquisition						Time:	705.8114	Sec	4/10/2014 10:48:22 AM
Time	Axial Displacement	Axial Force	Axial Strain
Sec	mm	N	mm/mm
395.07147	-8.7356796	2764.3188	0.019907225
396.07147	-8.7356796	2729.0701	0.019893795
397.07147	-8.7423935	2752.5693	0.019913938
398.07147	-8.7356796	2750.8906	0.019920653
399.07147	-8.7356796	2703.8923	0.019907225
400.07147	-8.7356796	2707.2495	0.019907225
401.07147	-8.7356796	2749.2122	0.019934081
402.07147	-8.7390366	2729.0701	0.019920653
403.07147	-8.7390366	2745.8552	0.019940794
404.07147	-8.7356796	2730.7485	0.019934081
405.07147	-8.7289648	2695.4998	0.019920653
406.07147	-8.7390366	2712.2849	0.019934081
407.07147	-8.7356796	2722.3562	0.019927366
408.07147	-8.7323217	2717.3206	0.019934081
409.07147	-8.7356796	2693.8213	0.019927366
410.07147	-8.7356796	2648.5012	0.019907225
411.07147	-8.7390366	2685.4287	0.019927366
412.07147	-8.7323217	2626.6807	0.019907225
413.07147	-8.7323217	2594.7886	0.01990051
414.07147	-8.7356796	2630.0376	0.01990051
415.07147	-8.7423935	2638.4302	0.01990051
416.07147	-8.7356796	2633.3945	0.01990051
417.07147	-8.7323217	2658.5725	0.019907225
418.07147	-8.7356796	2677.0361	0.019920653
419.07147	-8.7423935	2596.4673	0.019893795
420.07147	-8.7390366	2616.6094	0.01990051
421.07147	-8.7323217	2668.6436	0.019913938
422.07147	-8.7356796	2616.6094	0.019907225
423.07147	-8.7356796	2648.5012	0.019913938
424.07147	-8.7356796	2601.5027	0.019893795
425.07147	-8.7356796	2677.0361	0.019913938
426.07147	-8.7356796	2685.4287	0.019920653
427.07147	-8.7390366	2695.4998	0.019927366
428.07147	-8.7356796	2658.5725	0.019913938
429.07147	-8.7356796	2702.2139	0.019920653
430.07147	-8.7323217	2683.7502	0.019913938
431.07147	-8.7390366	2685.4287	0.019920653
432.07147	-8.7356796	2712.2849	0.019934081
433.07147	-8.7390366	2730.7485	0.019940794
434.07147	-8.7423935	2698.8569	0.019934081
435.07147	-8.7323217	2734.1055	0.019947508
436.07147	-8.7390366	2646.8228	0.019913938
437.07147	-8.7323217	2665.2864	0.019920653
438.07147	-8.7323217	2663.6079	0.019927366
439.07147	-8.7356796	2651.8584	0.019927366
440.07147	-8.7390366	2666.9651	0.019920653
441.07147	-8.7356796	2643.4658	0.019920653
442.07147	-8.7390366	2666.9651	0.019934081
443.07147	-8.7323217	2651.8584	0.019920653
444.07147	-8.7356796	2650.1799	0.019927366
445.07147	-8.7390366	2638.4302	0.019913938
446.07147	-8.7356796	2636.7517	0.019913938
447.07147	-8.7356796	2631.7161	0.019920653
448.07147	-8.7356796	2603.1812	0.019920653
449.07147	-8.7356796	2661.9294	0.019934081
450.07147	-8.7390366	2680.3931	0.019934081
451.07147	-8.7390366	2646.8228	0.019920653
452.07147	-8.7323217	2618.2878	0.019913938
453.07147	-8.7356796	2645.1443	0.019913938
454.07147	-8.7356796	2606.5383	0.01990051
455.07147	-8.7356796	2630.0376	0.019913938
456.07147	-8.7356796	2643.4658	0.019913938
457.07147	-8.7390366	2675.3577	0.019940794
458.07147	-8.7390366	2581.3606	0.019907225
459.07147	-8.7356796	2593.1101	0.019907225
460.07147	-8.7390366	2625.002	0.019893795
461.07147	-8.7390366	2625.002	0.019913938
462.07147	-8.7323217	2650.1799	0.019927366
463.07147	-8.7356796	2648.5012	0.019913938
464.07147	-8.7356796	2678.7146	0.019927366
465.07147	-8.7356796	2656.8938	0.019920653
466.07147	-8.7390366	2614.9309	0.019913938
467.07147	-8.7323217	2619.9666	0.019907225
468.07147	-8.7390366	2677.0361	0.019927366
469.07147	-8.7323217	2680.3931	0.019934081
470.07147	-8.7390366	2616.6094	0.019913938
471.07147	-8.7356796	2658.5725	0.019927366
472.07147	-8.7356796	2688.7856	0.019927366
473.07147	-8.7423935	2628.3591	0.01990051
474.07147	-8.7356796	2683.7502	0.019934081
475.07147	-8.7356796	2685.4287	0.019934081
476.07147	-8.7356796	2673.6792	0.019927366
477.07147	-8.7356796	2645.1443	0.019934081
478.07147	-8.7356796	2618.2878	0.019920653
479.07147	-8.7323217	2646.8228	0.019934081
480.07147	-8.7356796	2646.8228	0.019927366
481.07147	-8.7356796	2651.8584	0.019920653
482.07147	-8.7356796	2695.4998	0.019934081
483.07147	-8.7323217	2653.5369	0.019913938
484.07147	-8.7390366	2660.251	0.019934081
485.07147	-8.7390366	2670.322	0.019940794
486.07147	-8.7356796	2668.6436	0.019934081
487.07147	-8.7356796	2707.2495	0.019954223
488.07147	-8.7390366	2643.4658	0.019934081
489.07147	-8.7289648	2630.0376	0.019927366
490.07147	-8.7323217	2630.0376	0.019927366
491.07147	-8.7390366	2655.2153	0.019920653
492.07147	-8.7356796	2630.0376	0.019920653
493.07147	-8.7390366	2561.2183	0.01990051
494.07147	-8.7390366	2554.5042	0.01990051
495.07147	-8.7356796	2635.0732	0.019920653
496.07147	-8.7356796	2619.9666	0.019927366
497.07147	-8.7356796	2596.4673	0.019913938
498.07147	-8.7356796	2613.2524	0.019913938
499.07147	-8.7356796	2609.8953	0.019913938
500.07147	-8.7356796	2660.251	0.019934081
501.07147	-8.7356796	2630.0376	0.019920653
502.07147	-8.7356796	2660.251	0.019920653
503.07147	-8.7356796	2643.4658	0.019927366
504.07147	-8.7390366	2609.8953	0.019907225
505.07147	-8.7390366	2616.6094	0.019920653
506.07147	-8.7390366	2613.2524	0.019907225
507.07147	-8.7390366	2645.1443	0.019920653
508.07147	-8.7390366	2613.2524	0.019907225
509.07147	-8.7356796	2636.7517	0.019913938
510.07147	-8.7323217	2611.574	0.019920653
511.07147	-8.7390366	2631.7161	0.019907225
512.07147	-8.7323217	2646.8228	0.019913938
513.07147	-8.7356796	2593.1101	0.01990051
514.07147	-8.7390366	2603.1812	0.019913938
515.07147	-8.7356796	2549.4688	0.019893795
516.07147	-8.7356796	2638.4302	0.019920653
517.07147	-8.7356796	2646.8228	0.019920653
518.07147	-8.7390366	2576.325	0.01990051
519.07147	-8.7356796	2640.1086	0.019927366
520.07147	-8.7356796	2626.6807	0.019913938
521.07147	-8.7390366	2608.2168	0.019913938
522.07147	-8.7390366	2668.6436	0.019927366
523.07147	-8.7390366	2603.1812	0.019907225
524.07147	-8.7356796	2692.1428	0.019927366
525.07147	-8.7356796	2621.645	0.019920653
526.07147	-8.7390366	2589.7532	0.01990051
527.07147	-8.7323217	2604.8599	0.019913938
528.07147	-8.7323217	2599.8242	0.019920653
529.07147	-8.7289648	2641.7871	0.019934081
530.07147	-8.7323217	2618.2878	0.019907225
531.07147	-8.7390366	2628.3591	0.019920653
532.07147	-8.7323217	2606.5383	0.019913938
533.07147	-8.7323217	2697.1785	0.019940794
534.07147	-8.7390366	2678.7146	0.019947508
535.07147	-8.7356796	2687.1072	0.019940794
536.07147	-8.7356796	2690.4644	0.019934081
537.07147	-8.7323217	2695.4998	0.019947508
538.07147	-8.7323217	2655.2153	0.019927366
539.07147	-8.7356796	2702.2139	0.019947508
540.07147	-8.7356796	2604.8599	0.019920653
541.07147	-8.7356796	2687.1072	0.019940794
542.07147	-8.7356796	2655.2153	0.019934081
543.07147	-8.7390366	2635.0732	0.019920653
544.07147	-8.7390366	2712.2849	0.019947508
545.07147	-8.7356796	2646.8228	0.019927366
546.07147	-8.7390366	2636.7517	0.019920653
547.07147	-8.7356796	2625.002	0.019927366
548.07147	-8.7356796	2651.8584	0.019927366
549.07147	-8.7356796	2653.5369	0.019940794
550.07147	-8.7390366	2670.322	0.019947508
551.07147	-8.7390366	2658.5725	0.019927366
552.07147	-8.7356796	2658.5725	0.019934081
553.07147	-8.7356796	2660.251	0.019940794
554.07147	-8.7356796	2658.5725	0.019940794
555.07147	-8.7356796	2648.5012	0.019913938
556.07147	-8.7390366	2641.7871	0.019934081
557.07147	-8.7356796	2650.1799	0.019934081
558.07147	-8.7323217	2665.2864	0.019934081
559.07147	-8.7390366	2645.1443	0.019927366
560.07147	-8.7356796	2631.7161	0.019940794
561.07147	-8.7356796	2552.8257	0.01990051
562.07147	-8.7356796	2578.0034	0.019920653
563.07147	-8.7390366	2606.5383	0.019913938
564.07147	-8.7356796	2591.4316	0.01990051
565.07147	-8.7356796	2589.7532	0.019907225
566.07147	-8.7390366	2561.2183	0.01990051
567.07147	-8.7390366	2613.2524	0.019920653
568.07147	-8.7356796	2569.6108	0.019907225
569.07147	-8.7356796	2616.6094	0.019913938
570.07147	-8.7323217	2581.3606	0.019907225
571.07147	-8.7390366	2591.4316	0.019920653
572.07147	-8.7356796	2584.7175	0.019907225
573.07147	-8.7390366	2562.8967	0.01990051
574.07147	-8.7390366	2581.3606	0.019920653
575.07147	-8.7423935	2525.9695	0.019887082
576.07147	-8.7356796	2623.3235	0.019920653
577.07147	-8.7356796	2643.4658	0.019927366
578.07147	-8.7356796	2648.5012	0.019934081
579.07147	-8.7356796	2693.8213	0.019947508
580.07147	-8.7356796	2722.3562	0.019960936
581.07147	-8.7323217	2650.1799	0.019934081
582.07147	-8.7356796	2604.8599	0.019927366
583.07147	-8.7390366	2665.2864	0.019947508
584.07147	-8.7323217	2648.5012	0.019940794
585.07147	-8.7356796	2673.6792	0.019960936
586.07147	-8.7390366	2635.0732	0.019934081
587.07147	-8.7390366	2571.2893	0.019907225
588.07147	-8.7356796	2567.9324	0.019913938
589.07147	-8.7390366	2625.002	0.019927366
590.07147	-8.7356796	2616.6094	0.019927366
591.07147	-8.7356796	2621.645	0.019934081
592.07147	-8.7356796	2583.0391	0.019920653
593.07147	-8.7390366	2641.7871	0.019940794
594.07147	-8.7356796	2593.1101	0.019913938
595.07147	-8.7390366	2569.6108	0.019913938
596.07147	-8.7356796	2631.7161	0.019927366
597.07147	-8.7356796	2596.4673	0.019920653
598.07147	-8.7390366	2566.2539	0.019907225
599.07147	-8.7390366	2604.8599	0.019920653
600.07147	-8.7390366	2660.251	0.019934081
601.07147	-8.7356796	2638.4302	0.019934081
602.07147	-8.7323217	2635.0732	0.019927366
603.07147	-8.7356796	2621.645	0.019927366
604.07147	-8.7423935	2616.6094	0.019913938
605.07147	-8.7356796	2510.8628	0.019887082
606.07147	-8.7356796	2566.2539	0.019913938
607.07147	-8.7356796	2625.002	0.019927366
608.07147	-8.7390366	2578.0034	0.019913938
609.07147	-8.7390366	2584.7175	0.019913938
610.07147	-8.7390366	2687.1072	0.019947508
611.07147	-8.7356796	2665.2864	0.019940794
612.07147	-8.7356796	2660.251	0.019940794
613.07147	-8.7356796	2655.2153	0.019940794
614.07147	-8.7390366	2623.3235	0.019927366
615.07147	-8.7356796	2609.8953	0.019920653
616.07147	-8.7356796	2566.2539	0.019907225
617.07147	-8.7390366	2601.5027	0.019913938
618.07147	-8.7356796	2619.9666	0.019927366
619.07147	-8.7356796	2608.2168	0.019920653
620.07147	-8.7323217	2626.6807	0.019920653
621.07147	-8.7390366	2593.1101	0.019913938
622.07147	-8.7356796	2566.2539	0.019907225
623.07147	-8.7390366	2614.9309	0.019927366
624.07147	-8.7390366	2603.1812	0.019913938
625.07147	-8.7390366	2608.2168	0.019927366
626.07147	-8.7356796	2599.8242	0.019934081
627.07147	-8.7323217	2616.6094	0.019934081
[...]
2250.2122	0.57314688	4234.7007	0.14899197
2250.2222	0.57314688	4246.4502	0.1490054
2250.2319	0.57652074	4256.5215	0.14901212
2250.2419	0.57652074	4249.8071	0.14901884
2250.252	0.57652074	4241.415	0.14901884
2250.2617	0.57314688	4238.0576	0.14901884
2250.2717	0.57989454	4256.5215	0.14901884
2250.2817	0.57989454	4259.8784	0.14902554
2250.2915	0.57989454	4248.1289	0.14903226
2250.3015	0.57314688	4234.7007	0.14903226
2250.3115	0.57989454	4241.415	0.14904569
2250.3213	0.57989454	4261.5571	0.14904569
2250.3313	0.57652074	4264.9141	0.14905912
2250.3413	0.57652074	4244.772	0.14905912
2250.3511	0.57652074	4241.415	0.14905912
2250.3611	0.57652074	4246.4502	0.14907926
2250.3711	0.57989454	4259.8784	0.14907926
2250.3809	0.58326834	4259.8784	0.14907926
2250.3909	0.58326834	4244.772	0.14909269
2250.4009	0.58326834	4249.8071	0.14909269
2250.4106	0.58326834	4246.4502	0.14909939
2250.4207	0.57989454	4254.8428	0.14909939
2250.4307	0.57652074	4258.2002	0.14910612
2250.4404	0.58326834	4244.772	0.14911284
2250.4504	0.58326834	4246.4502	0.14911284
2250.4604	0.57989454	4249.8071	0.14911284
2250.4702	0.58326834	4259.8784	0.14912626
2250.4802	0.58326834	4258.2002	0.14913297
2250.4902	0.57989454	4246.4502	0.14914639
2250.5	0.57989454	4244.772	0.14913969
2250.51	0.58326834	4254.8428	0.14914639
2250.52	0.58326834	4264.9141	0.14915311
2250.5298	0.58664221	4254.8428	0.14915983
2250.5398	0.57989454	4244.772	0.14915983
2250.5498	0.58326834	4253.1641	0.14916654
2250.5596	0.57989454	4263.2354	0.14917326
2250.5696	0.59001601	4261.5571	0.14918669
2250.5796	0.58664221	4249.8071	0.14919339
2250.5894	0.58664221	4241.415	0.14918669
2250.5994	0.58664221	4256.5215	0.14919339
2250.6094	0.58664221	4266.5923	0.14920011
2250.6191	0.58664221	4251.4858	0.14920683
2250.6292	0.59338987	4238.0576	0.14920683
2250.6392	0.59001601	4243.0933	0.14922026
2250.6489	0.59001601	4259.8784	0.14922026
2250.6589	0.59338987	4266.5923	0.14922696
2250.6689	0.59001601	4248.1289	0.14923368
2250.6787	0.59001601	4243.0933	0.14924039
2250.6887	0.59001601	4249.8071	0.14924711
2250.6987	0.59338987	4259.8784	0.14924711
2250.7085	0.58664221	4259.8784	0.14924711
2250.7185	0.59338987	4248.1289	0.14925383
2250.7285	0.59001601	4246.4502	0.14925383
2250.7383	0.59338987	4244.772	0.14927396
2250.7483	0.59001601	4256.5215	0.14926054
2250.7583	0.59338987	4261.5571	0.14926726
2250.7681	0.59338987	4248.1289	0.14928068
2250.7781	0.59676367	4241.415	0.14927396
2250.7881	0.59338987	4239.7358	0.14928068
2250.7979	0.59338987	4256.5215	0.14928739
2250.8079	0.59338987	4258.2002	0.14929411
2250.8179	0.59001601	4243.0933	0.14930083
2250.8276	0.59676367	4243.0933	0.14931425
2250.8376	0.59338987	4244.772	0.14931425
2250.8477	0.60013747	4256.5215	0.14930753
2250.8574	0.60013747	4254.8428	0.14931425
2250.8674	0.59338987	4244.772	0.14932096
2250.8774	0.59676367	4243.0933	0.14932768
2250.8872	0.60013747	4254.8428	0.1493344
2250.8972	0.59676367	4259.8784	0.14934111
2250.9072	0.60013747	4249.8071	0.14934783
2250.917	0.59338987	4239.7358	0.14934111
2250.927	0.59676367	4251.4858	0.14935453
2250.937	0.59338987	4263.2354	0.14935453
2250.9468	0.59676367	4258.2002	0.14936796
2250.9568	0.60013747	4244.772	0.14937468
2250.9668	0.59676367	4243.0933	0.1493814
2250.9766	0.60013747	4261.5571	0.1493881
2250.9866	0.59676367	4261.5571	0.14939483
2250.9966	0.60013747	4251.4858	0.14939483
2251.0063	0.59676367	4246.4502	0.14940153
2251.0164	0.60013747	4248.1289	0.14940825
2251.0264	0.60013747	4261.5571	0.14940825
2251.0361	0.60013747	4263.2354	0.14942168
2251.0461	0.60351133	4253.1641	0.1494284
2251.0562	0.60013747	4246.4502	0.1494284
2251.0659	0.60013747	4246.4502	0.14944182
2251.0759	0.60013747	4258.2002	0.1494284
2251.0859	0.60688514	4261.5571	0.14944853
2251.0957	0.60351133	4251.4858	0.14944182
2251.1057	0.60351133	4249.8071	0.14945525
2251.1157	0.60351133	4244.772	0.14945525
2251.1255	0.61025894	4261.5571	0.14946195
2251.1355	0.60688514	4266.5923	0.14946195
2251.1455	0.60688514	4253.1641	0.1494754
2251.1553	0.60688514	4243.0933	0.1494821
2251.1653	0.60688514	4243.0933	0.1494821
2251.1753	0.60688514	4256.5215	0.1494754
2251.1851	0.60688514	4258.2002	0.1494821
2251.1951	0.60688514	4243.0933	0.14949553
2251.2051	0.61025894	4241.415	0.14948882
2251.2148	0.61025894	4251.4858	0.14949553
2251.2249	0.61025894	4263.2354	0.14949553
2251.2349	0.60688514	4251.4858	0.14948882
2251.2446	0.60688514	4243.0933	0.14950895
2251.2546	0.61025894	4249.8071	0.14952239
2251.2646	0.61025894	4258.2002	0.14952239
2251.2744	0.6136328	4258.2002	0.14952239
2251.2844	0.61025894	4249.8071	0.14953582
2251.2944	0.61025894	4244.772	0.14954253
2251.3042	0.61025894	4256.5215	0.14954253
2251.3142	0.6136328	4261.5571	0.14955595
2251.3242	0.6136328	4254.8428	0.14955595
2251.334	0.6136328	4248.1289	0.14955595
2251.344	0.6136328	4249.8071	0.14956939
2251.354	0.6136328	4259.8784	0.1495761
2251.3638	0.6136328	4266.5923	0.1495761
2251.3738	0.6136328	4254.8428	0.14958952
2251.3838	0.6170066	4251.4858	0.14958282
2251.3936	0.6170066	4246.4502	0.14960295
2251.4036	0.6136328	4256.5215	0.14960295
2251.4136	0.6136328	4264.9141	0.14961639
2251.4233	0.6170066	4253.1641	0.14960967
2251.4333	0.6136328	4246.4502	0.1496231
2251.4434	0.6136328	4243.0933	0.14960967
2251.4531	0.6136328	4258.2002	0.1496231
2251.4631	0.6170066	4268.271	0.14962982
2251.4731	0.6170066	4251.4858	0.14963652
2251.4829	0.6203804	4243.0933	0.14964995
2251.4929	0.6136328	4248.1289	0.14964995
2251.5029	0.6170066	4264.9141	0.14964324
2251.5127	0.6203804	4264.9141	0.14965667
2251.5227	0.6170066	4248.1289	0.14965667
2251.5327	0.6136328	4238.0576	0.14965667
2251.5425	0.6170066	4243.0933	0.14967681
2251.5525	0.6203804	4258.2002	0.14967681
2251.5625	0.6170066	4256.5215	0.14967009
2251.5723	0.6170066	4238.0576	0.14969024
2251.5823	0.62375426	4239.7358	0.14968352
2251.5923	0.6170066	4251.4858	0.14969024
2251.6021	0.6203804	4256.5215	0.14969695
2251.6121	0.62712806	4249.8071	0.14971039
2251.6221	0.6170066	4241.415	0.14970367
2251.6318	0.62375426	4248.1289	0.14971709
2251.6418	0.62375426	4254.8428	0.14972381
2251.6519	0.62375426	4254.8428	0.14972381
2251.6616	0.6203804	4249.8071	0.14973052
2251.6716	0.6203804	4243.0933	0.14973724
2251.6816	0.62375426	4251.4858	0.14973724
2251.6914	0.62375426	4258.2002	0.14973724
2251.7014	0.62375426	4256.5215	0.14974396
2251.7114	0.62375426	4246.4502	0.14974396
2251.7212	0.62712806	4246.4502	0.14976409
2251.7312	0.62375426	4253.1641	0.14975066
2251.7412	0.62375426	4261.5571	0.14976409
2251.751	0.62375426	4258.2002	0.14977752
2251.761	0.62712806	4246.4502	0.14978424
2251.771	0.62712806	4239.7358	0.14979096
2251.7808	0.62712806	4256.5215	0.14978424
2251.7908	0.62712806	4266.5923	0.14978424

Data Acquisition						Time:	2567.3398	Sec	4/10/2014 11:19:24 AM
Time	Axial Displacement	Axial Force	Axial Strain
Sec	mm	N	mm/mm
2252.8159	0.63050187	4159.1675	0.14985138
2253.8159	0.62375426	4105.4551	0.14983796
2254.8159	0.63050187	4103.7764	0.14985809
2255.8159	0.62712806	4081.9553	0.14985138
2256.8159	0.62712806	4085.3127	0.14986481
2257.8159	0.62712806	4122.2402	0.14987151
2258.8159	0.63387573	4123.9185	0.14989838
2259.8159	0.62712806	4080.2769	0.14987823
2260.8159	0.62712806	4050.0637	0.14986481
2261.8159	0.62712806	4039.9929	0.14987151
2262.8159	0.62712806	4018.1719	0.14985138
2263.8159	0.62712806	4013.1365	0.14985809
2264.8159	0.63050187	4028.2432	0.14987151
2265.8159	0.62712806	4028.2432	0.14987151
2266.8159	0.63387573	4041.6714	0.14989166
2267.8159	0.62712806	3987.9587	0.14985138
2268.8159	0.62712806	3962.781	0.14985138
2269.8159	0.63050187	3969.4949	0.14985809
2270.8159	0.62712806	3982.9231	0.14985809
2271.8159	0.63050187	4016.4934	0.14987823
2272.8159	0.62712806	4021.5293	0.14987151
2273.8159	0.62712806	4006.4226	0.14987823
2274.8159	0.62712806	4001.3867	0.14985809
2275.8159	0.62375426	4016.4934	0.14987151
2276.8159	0.63050187	3998.0298	0.14987823
2277.8159	0.62712806	4008.1011	0.14986481
2278.8159	0.63050187	4003.0652	0.14987823
2279.8159	0.62712806	3976.209	0.14986481
2280.8159	0.62712806	3979.5662	0.14986481
2281.8159	0.63050187	3956.0669	0.14985809
2282.8159	0.62375426	3967.8164	0.14987151
2283.8159	0.62712806	3979.5662	0.14985809
2284.8159	0.63050187	3989.6372	0.14987151
2285.8159	0.63050187	3967.8164	0.14985809
2286.8159	0.63387573	3996.3513	0.14987151
2287.8159	0.63050187	3989.6372	0.14987823
2288.8159	0.62712806	3989.6372	0.14986481
2289.8159	0.62712806	3972.8521	0.14987151
2290.8159	0.62375426	3954.3882	0.14985809
2291.8159	0.62375426	3987.9587	0.14987151
2292.8159	0.62375426	3989.6372	0.14985809
2293.8159	0.63050187	3986.2803	0.14987823
2294.8159	0.62712806	3969.4949	0.14985809
2295.8159	0.62712806	4018.1719	0.14987823
2296.8159	0.62712806	4013.1365	0.14988495
2297.8159	0.62375426	4008.1011	0.14989166
2298.8159	0.62375426	4029.9216	0.14990509
2299.8159	0.6203804	4009.7795	0.14988495
2300.8159	0.62712806	4006.4226	0.14989166
2301.8159	0.62712806	3991.3157	0.14988495
2302.8159	0.62712806	3976.209	0.14987823
2303.8159	0.63050187	3964.4595	0.14987151
2304.8159	0.62375426	4001.3867	0.14988495
2305.8159	0.63050187	3982.9231	0.14989166
2306.8159	0.62712806	3935.9246	0.14985809
2307.8159	0.62712806	3951.0313	0.14986481
2308.8159	0.62712806	3942.6387	0.14987823
2309.8159	0.62712806	3930.8889	0.14987823
2310.8159	0.63050187	3947.6743	0.14987151
2311.8159	0.63050187	3974.5305	0.14987823
2312.8159	0.62375426	3944.3171	0.14987151
2313.8159	0.63050187	3930.8889	0.14987151
2314.8159	0.63050187	3969.4949	0.14989166
2315.8159	0.62712806	3952.7097	0.14988495
2316.8159	0.62375426	3966.1379	0.14989166
2317.8159	0.62712806	3937.603	0.14987151
2318.8159	0.62712806	3977.8875	0.14989838
2319.8159	0.63050187	3957.7454	0.14987823
2320.8159	0.62375426	3967.8164	0.14987151
2321.8159	0.62712806	3940.9602	0.14987823
2322.8159	0.62712806	3952.7097	0.14988495
2323.8159	0.62712806	3957.7454	0.14987823
2324.8159	0.62712806	3974.5305	0.14989166
2325.8159	0.62712806	3905.7112	0.14987151
2326.8159	0.63050187	3951.0313	0.14988495
2327.8159	0.62712806	3996.3513	0.14989838
2328.8159	0.62712806	3967.8164	0.14987823
2329.8159	0.62375426	3912.4253	0.14986481
2330.8159	0.63050187	3935.9246	0.14987823
2331.8159	0.63050187	3915.7825	0.14985809
2332.8159	0.62712806	3932.5676	0.14986481
2333.8159	0.62712806	3969.4949	0.14989838
2334.8159	0.62375426	3900.6758	0.14986481
2335.8159	0.63050187	3964.4595	0.14987823
2336.8159	0.63050187	3964.4595	0.14988495
2337.8159	0.62712806	3969.4949	0.14989838
2338.8159	0.62712806	3934.2461	0.14988495
2339.8159	0.62712806	3961.1023	0.14989838
2340.8159	0.62375426	3956.0669	0.14988495
2341.8159	0.62375426	3944.3171	0.14988495
2342.8159	0.62375426	3951.0313	0.14987823
2343.8159	0.62712806	3914.1038	0.14986481
2344.8159	0.62712806	3947.6743	0.14987823
2345.8159	0.62712806	3930.8889	0.14987151
2346.8159	0.62712806	3945.9956	0.14987151
2347.8159	0.62375426	3904.0327	0.14987823
2348.8159	0.63050187	3942.6387	0.14988495
2349.8159	0.62712806	3957.7454	0.14988495
2350.8159	0.62712806	3961.1023	0.14989838
2351.8159	0.62712806	3937.603	0.14988495
2352.8159	0.62375426	3952.7097	0.14988495
2353.8159	0.62712806	3944.3171	0.14987823
2354.8159	0.62712806	3915.7825	0.14985809
2355.8159	0.62375426	3919.1394	0.14987151
2356.8159	0.62375426	3937.603	0.14987151
2357.8159	0.62712806	3919.1394	0.14986481
2358.8159	0.62712806	3956.0669	0.14987823
2359.8159	0.62712806	3930.8889	0.14986481
2360.8159	0.62712806	3912.4253	0.14985809
2361.8159	0.63050187	3887.2476	0.14985809
2362.8159	0.63050187	3875.4978	0.14985809
2363.8159	0.62712806	3897.3186	0.14984466
2364.8159	0.62712806	3880.5334	0.14984466
2365.8159	0.62712806	3914.1038	0.14986481
2366.8159	0.62712806	3917.4609	0.14987823
2367.8159	0.63050187	3907.3896	0.14986481
2368.8159	0.63050187	3932.5676	0.14986481
2369.8159	0.62712806	3952.7097	0.14988495
2370.8159	0.63050187	3919.1394	0.14987823
2371.8159	0.62712806	3920.8179	0.14987823
2372.8159	0.63050187	3976.209	0.14989166
2373.8159	0.62712806	3947.6743	0.14988495
2374.8159	0.62712806	3939.2817	0.14988495
2375.8159	0.62375426	3937.603	0.14987823
2376.8159	0.62712806	3942.6387	0.14987151
2377.8159	0.62375426	3925.8535	0.14987823
2378.8159	0.62375426	3930.8889	0.14987823
2379.8159	0.63050187	3925.8535	0.14987823
2380.8159	0.62712806	3925.8535	0.14986481
2381.8159	0.63050187	3902.3542	0.14986481
2382.8159	0.62712806	3897.3186	0.14987151
2383.8159	0.62375426	3927.532	0.14987823
2384.8159	0.63050187	3905.7112	0.14986481
2385.8159	0.62375426	3942.6387	0.14988495
2386.8159	0.62712806	3880.5334	0.14985809
2387.8159	0.63050187	3909.0684	0.14985809
2388.8159	0.62712806	3937.603	0.14987823
2389.8159	0.62712806	3904.0327	0.14986481
2390.8159	0.63050187	3959.4238	0.14989166
2391.8159	0.62712806	3932.5676	0.14987823
2392.8159	0.62712806	3935.9246	0.14988495
2393.8159	0.62712806	3920.8179	0.14988495
2394.8159	0.63050187	3920.8179	0.14987151
2395.8159	0.6203804	3890.6045	0.14987151
2396.8159	0.63050187	3895.6401	0.14986481
2397.8159	0.62712806	3917.4609	0.14987823
2398.8159	0.62712806	3868.7837	0.14985809
2399.8159	0.62375426	3892.2832	0.14986481
2400.8159	0.62375426	3851.9985	0.14983796
2401.8159	0.62712806	3857.0342	0.14985138
2402.8159	0.63050187	3870.4624	0.14985138
2403.8159	0.63050187	3846.9631	0.14984466
2404.8159	0.62712806	3830.178	0.14983796
2405.8159	0.62712806	3813.3926	0.14982451
2406.8159	0.62712806	3851.9985	0.14983124
2407.8159	0.63050187	3850.3201	0.14983796
2408.8159	0.62712806	3872.1409	0.14986481
2409.8159	0.62712806	3912.4253	0.14986481
2410.8159	0.63050187	3907.3896	0.14986481
2411.8159	0.62712806	3868.7837	0.14984466
2412.8159	0.62375426	3890.6045	0.14986481
2413.8159	0.62375426	3848.6416	0.14983796
2414.8159	0.62712806	3872.1409	0.14984466
2415.8159	0.6203804	3897.3186	0.14986481
2416.8159	0.62712806	3858.7126	0.14983796
2417.8159	0.62375426	3909.0684	0.14987823
2418.8159	0.62712806	3857.0342	0.14985138
2419.8159	0.62712806	3887.2476	0.14985809
2420.8159	0.62712806	3924.175	0.14987151
2421.8159	0.62712806	3890.6045	0.14986481
2422.8159	0.63050187	3855.3557	0.14985138
2423.8159	0.62712806	3853.6772	0.14985809
2424.8159	0.63050187	3863.7483	0.14985809
2425.8159	0.62712806	3845.2844	0.14985138
2426.8159	0.62375426	3868.7837	0.14983796
2427.8159	0.62712806	3875.4978	0.14984466
2428.8159	0.62375426	3862.0698	0.14984466
2429.8159	0.63050187	3882.2119	0.14985138
2430.8159	0.63050187	3915.7825	0.14986481
2431.8159	0.62375426	3887.2476	0.14986481
2432.8159	0.63387573	3939.2817	0.14988495
2433.8159	0.63050187	3885.5691	0.14987151
2434.8159	0.62712806	3883.8904	0.14985809
2435.8159	0.63050187	3905.7112	0.14987151
2436.8159	0.63050187	3897.3186	0.14985809
2437.8159	0.62712806	3882.2119	0.14985809
2438.8159	0.62712806	3873.8193	0.14985809
2439.8159	0.63050187	3870.4624	0.14984466
2440.8159	0.62712806	3870.4624	0.14985138
2441.8159	0.62375426	3867.1052	0.14985138
2442.8159	0.63387573	3885.5691	0.14986481
2443.8159	0.62375426	3793.2505	0.14981781
2444.8159	0.62712806	3855.3557	0.14985809
2445.8159	0.62712806	3863.7483	0.14984466
2446.8159	0.62712806	3823.4639	0.14982451
2447.8159	0.62712806	3833.5349	0.14983124
2448.8159	0.62375426	3863.7483	0.14984466
2449.8159	0.62712806	3841.9275	0.14983124
2450.8159	0.63050187	3850.3201	0.14983796
2451.8159	0.63050187	3863.7483	0.14985138
2452.8159	0.6203804	3836.8918	0.14984466
2453.8159	0.62712806	3882.2119	0.14984466
2454.8159	0.62712806	3885.5691	0.14986481
2455.8159	0.63050187	3868.7837	0.14985138
2456.8159	0.63387573	3870.4624	0.14985809
2457.8159	0.62712806	3892.2832	0.14986481
2458.8159	0.62712806	3882.2119	0.14985138
2459.8159	0.63050187	3882.2119	0.14986481
2460.8159	0.63050187	3840.249	0.14983796
2461.8159	0.62712806	3890.6045	0.14988495
2462.8159	0.62712806	3954.3882	0.14989166
2463.8159	0.62712806	3917.4609	0.14988495
2464.8159	0.62712806	3893.9617	0.14986481
2465.8159	0.62375426	3942.6387	0.14988495
2466.8159	0.63050187	3865.4268	0.14985809
2467.8159	0.62712806	3907.3896	0.14987823
2468.8159	0.62712806	3872.1409	0.14986481
2469.8159	0.62375426	3865.4268	0.14985138
2470.8159	0.62712806	3895.6401	0.14987823
2471.8159	0.62712806	3912.4253	0.14987823
2472.8159	0.62712806	3937.603	0.14988495
2473.8159	0.62712806	3944.3171	0.14989838
2474.8159	0.62712806	3922.4963	0.14989838
2475.8159	0.62712806	3887.2476	0.14987151
2476.8159	0.62712806	3915.7825	0.14987823
2477.8159	0.62712806	3878.855	0.14987823
2478.8159	0.63050187	3888.926	0.14985809
2479.8159	0.62375426	3888.926	0.14987151
2480.8159	0.63050187	3920.8179	0.14988495
2481.8159	0.62712806	3885.5691	0.14987823
2482.8159	0.62712806	3915.7825	0.14986481
2483.8159	0.62712806	3900.6758	0.14988495
2484.8159	0.63050187	3930.8889	0.14988495
2485.8159	0.63050187	3888.926	0.14987823
2486.8159	0.63050187	3850.3201	0.14984466
2487.8159	0.62712806	3810.0356	0.14983796
2488.8159	0.63050187	3873.8193	0.14986481
2489.8159	0.62375426	3833.5349	0.14985138
2490.8159	0.63387573	3904.0327	0.14986481
2491.8159	0.62375426	3862.0698	0.14985809
2492.8159	0.62712806	3836.8918	0.14983796
2493.8159	0.62712806	3850.3201	0.14983796
2494.8159	0.62712806	3838.5706	0.14984466
2495.8159	0.62712806	3840.249	0.14984466
2496.8159	0.63050187	3863.7483	0.14985809
2497.8159	0.63050187	3855.3557	0.14984466
2498.8159	0.62712806	3858.7126	0.14985809
2499.8159	0.62712806	3887.2476	0.14985809
2500.8159	0.63050187	3843.606	0.14986481
2501.8159	0.62712806	3845.2844	0.14983796
2502.8159	0.62712806	3846.9631	0.14984466
2503.8159	0.62375426	3853.6772	0.14985809
2504.8159	0.63050187	3867.1052	0.14985138
2505.8159	0.62712806	3875.4978	0.14987151
2506.8159	0.62712806	3914.1038	0.14987151
2507.8159	0.63050187	3947.6743	0.14989166
2508.8159	0.62375426	3924.175	0.14987823
2509.8159	0.62712806	3959.4238	0.14989838
2510.8159	0.62712806	3883.8904	0.14987151
2511.8159	0.62375426	3919.1394	0.14987151
2512.8159	0.63050187	3885.5691	0.14985809
2513.8159	0.62712806	3888.926	0.14986481
2514.8159	0.62712806	3878.855	0.14985809
2515.8159	0.62375426	3875.4978	0.14987151
2516.8159	0.62712806	3930.8889	0.14987823
2517.8159	0.62712806	3904.0327	0.14988495
2518.8159	0.62375426	3890.6045	0.14987151
2519.8159	0.62712806	3904.0327	0.14986481
2520.8159	0.62712806	3867.1052	0.14986481
2521.8159	0.62375426	3914.1038	0.14987151
2522.8159	0.62712806	3878.855	0.14986481
2523.8159	0.62712806	3857.0342	0.14987151
2524.8159	0.62712806	3875.4978	0.14985809
2525.8159	0.62712806	3798.2859	0.14981781
2526.8159	0.62712806	3828.4993	0.14984466
2527.8159	0.63050187	3873.8193	0.14985809
2528.8159	0.62712806	3811.7141	0.14984466
2529.8159	0.62712806	3831.8564	0.14984466
2530.8159	0.62375426	3855.3557	0.14985809
2531.8159	0.62712806	3870.4624	0.14987151
2532.8159	0.63050187	3914.1038	0.14987823
2533.8159	0.62712806	3909.0684	0.14989166
2534.8159	0.63050187	3898.9971	0.14987823
2535.8159	0.63050187	3857.0342	0.14985809
2536.8159	0.62712806	3870.4624	0.14987151
2537.8159	0.63050187	3880.5334	0.14987151
2538.8159	0.62375426	3878.855	0.14985138
2539.8159	0.62712806	3870.4624	0.14986481
2540.8159	0.62712806	3848.6416	0.14985138
2541.8159	0.62712806	3930.8889	0.14987823
2542.8159	0.62375426	3855.3557	0.14985138
2543.8159	0.63050187	3851.9985	0.14984466
2544.8159	0.63050187	3873.8193	0.14985809
2545.8159	0.62712806	3868.7837	0.14985138
2546.8159	0.62375426	3887.2476	0.14985809
2547.8159	0.63050187	3919.1394	0.14987823
2548.8159	0.62712806	3900.6758	0.14987151
2549.8159	0.63050187	3873.8193	0.14985809
2550.8159	0.62712806	3905.7112	0.14987151
2551.8159	0.62375426	3868.7837	0.14986481
2552.8159	0.6203804	3893.9617	0.14986481
2553.8159	0.62375426	3934.2461	0.14988495
2554.8159	0.62712806	3947.6743	0.14990509
2555.8159	0.62712806	3907.3896	0.14987823
2556.8159	0.62712806	3925.8535	0.14988495
2557.8159	0.62712806	3912.4253	0.14988495
2558.8159	0.63050187	3895.6401	0.14987151
2559.8159	0.62712806	3872.1409	0.14984466
2560.8159	0.62712806	3875.4978	0.14987151
2561.8159	0.62375426	3890.6045	0.14987151
2562.8159	0.62712806	3885.5691	0.14985809
2563.8159	0.62712806	3897.3186	0.14987151
2564.8159	0.62712806	3880.5334	0.14987151
2565.8159	0.6203804	3900.6758	0.14986481
2566.8159	0.62375426	3917.4609	0.14988495